#VRML_SIM R2021a utf8
WorldInfo {
  coordinateSystem "NUE"
}
Viewpoint {
  orientation -0.5107595724777394 0.8137433029494165 0.2773923142903043 1.1546993938711552
  position 0.9520862320684298 0.9204547113857162 0.7329325422505979
}
TexturedBackground {
}
TexturedBackgroundLight {
}
RectangleArena {
}
Robot {
  translation 0 0.1 0
  children [
    Transform {
      children [
        DEF body Shape {
          appearance PBRAppearance {
            baseColor 0 1 1
            roughness 1
            metalness 0
          }
          geometry Box {
            size 0.1 0.2 0.1
          }
        }
      ]
    }
    HingeJoint {
      jointParameters HingeJointParameters {
        axis 0 0 1
        anchor 0 0.05 0.075
      }
      device [
        RotationalMotor {
          name "motor"
        }
        PositionSensor {
          name "ps"
        }
      ]
      endPoint Solid {
        translation 0 0.05 0.075
        rotation 0 0 1 0
        children [
          DEF axle Shape {
            appearance PBRAppearance {
              baseColor 1 0 0
              roughness 1
              metalness 0
            }
            geometry Box {
              size 0.05 0.05 0.05
            }
          }
          Solid {
            translation 0.075 0 0.05
            children [
              DEF arm Shape {
                appearance PBRAppearance {
                  baseColor 1 0 1
                  roughness 1
                  metalness 0
                }
                geometry Box {
                  size 0.2 0.05 0.05
                }
              }
            ]
            boundingObject USE arm
            physics Physics {
            }
          }
        ]
        boundingObject USE axle
        physics Physics {
        }
      }
    }
  ]
  boundingObject USE body
  physics Physics {
  }
  controller "arm_tutorial"
}
